Traceback (most recent call last):
  File "/home/runner/micromamba-root/envs/clivar/lib/python3.10/site-packages/jupyter_cache/executors/utils.py", line 51, in single_nb_execution
    executenb(
  File "/home/runner/micromamba-root/envs/clivar/lib/python3.10/site-packages/nbclient/client.py", line 1204, in execute
    return NotebookClient(nb=nb, resources=resources, km=km, **kwargs).execute()
  File "/home/runner/micromamba-root/envs/clivar/lib/python3.10/site-packages/nbclient/util.py", line 84, in wrapped
    return just_run(coro(*args, **kwargs))
  File "/home/runner/micromamba-root/envs/clivar/lib/python3.10/site-packages/nbclient/util.py", line 62, in just_run
    return loop.run_until_complete(coro)
  File "/home/runner/micromamba-root/envs/clivar/lib/python3.10/asyncio/base_events.py", line 649, in run_until_complete
    return future.result()
  File "/home/runner/micromamba-root/envs/clivar/lib/python3.10/site-packages/nbclient/client.py", line 663, in async_execute
    await self.async_execute_cell(
  File "/home/runner/micromamba-root/envs/clivar/lib/python3.10/site-packages/nbclient/client.py", line 965, in async_execute_cell
    await self._check_raise_for_error(cell, cell_index, exec_reply)
  File "/home/runner/micromamba-root/envs/clivar/lib/python3.10/site-packages/nbclient/client.py", line 862, in _check_raise_for_error
    raise CellExecutionError.from_cell_and_msg(cell, exec_reply_content)
nbclient.exceptions.CellExecutionError: An error occurred while executing the following cell:
------------------
# supress warnings
import warnings

warnings.filterwarnings("ignore")  # don't output warnings

import os

# import packages
import xarray as xr

xr.set_options(display_style="html")
import intake
import cftime
import cartopy.crs as ccrs
import matplotlib.pyplot as plt
import matplotlib.path as mpath
import numpy as np
import xesmf as xe
from cmcrameri import cm

%matplotlib inline
------------------

[0;31m---------------------------------------------------------------------------[0m
[0;31mModuleNotFoundError[0m                       Traceback (most recent call last)
Cell [0;32mIn[1], line 18[0m
[1;32m     16[0m [38;5;28;01mimport[39;00m [38;5;21;01mmatplotlib[39;00m[38;5;21;01m.[39;00m[38;5;21;01mpath[39;00m [38;5;28;01mas[39;00m [38;5;21;01mmpath[39;00m
[1;32m     17[0m [38;5;28;01mimport[39;00m [38;5;21;01mnumpy[39;00m [38;5;28;01mas[39;00m [38;5;21;01mnp[39;00m
[0;32m---> 18[0m [38;5;28;01mimport[39;00m [38;5;21;01mxesmf[39;00m [38;5;28;01mas[39;00m [38;5;21;01mxe[39;00m
[1;32m     19[0m [38;5;28;01mfrom[39;00m [38;5;21;01mcmcrameri[39;00m [38;5;28;01mimport[39;00m cm
[1;32m     21[0m get_ipython()[38;5;241m.[39mrun_line_magic([38;5;124m'[39m[38;5;124mmatplotlib[39m[38;5;124m'[39m, [38;5;124m'[39m[38;5;124minline[39m[38;5;124m'[39m)

[0;31mModuleNotFoundError[0m: No module named 'xesmf'
ModuleNotFoundError: No module named 'xesmf'

